[2025-01-25T12:22:21.424+0000] {taskinstance.py:1157} INFO - Dependencies all met for dep_context=non-requeueable deps ti=<TaskInstance: openweather_data_lake.data_to_raw manual__2025-01-25T12:22:19.895689+00:00 [queued]>
[2025-01-25T12:22:21.428+0000] {taskinstance.py:1157} INFO - Dependencies all met for dep_context=requeueable deps ti=<TaskInstance: openweather_data_lake.data_to_raw manual__2025-01-25T12:22:19.895689+00:00 [queued]>
[2025-01-25T12:22:21.428+0000] {taskinstance.py:1359} INFO - Starting attempt 1 of 3
[2025-01-25T12:22:21.434+0000] {taskinstance.py:1380} INFO - Executing <Task(PythonOperator): data_to_raw> on 2025-01-25 12:22:19.895689+00:00
[2025-01-25T12:22:21.438+0000] {standard_task_runner.py:57} INFO - Started process 390 to run task
[2025-01-25T12:22:21.441+0000] {standard_task_runner.py:84} INFO - Running: ['***', 'tasks', 'run', 'openweather_data_lake', 'data_to_raw', 'manual__2025-01-25T12:22:19.895689+00:00', '--job-id', '6', '--raw', '--subdir', 'DAGS_FOLDER/openweather_data_lake.py', '--cfg-path', '/tmp/tmpfippnwrm']
[2025-01-25T12:22:21.443+0000] {standard_task_runner.py:85} INFO - Job 6: Subtask data_to_raw
[2025-01-25T12:22:21.455+0000] {logging_mixin.py:151} WARNING - /home/***/.local/lib/python3.8/site-packages/***/settings.py:195 DeprecationWarning: The sql_alchemy_conn option in [core] has been moved to the sql_alchemy_conn option in [database] - the old setting has been used, but please update your config.
[2025-01-25T12:22:21.479+0000] {task_command.py:415} INFO - Running <TaskInstance: openweather_data_lake.data_to_raw manual__2025-01-25T12:22:19.895689+00:00 [running]> on host c5085a2172b1
[2025-01-25T12:22:21.528+0000] {taskinstance.py:1660} INFO - Exporting env vars: AIRFLOW_CTX_DAG_OWNER='***' AIRFLOW_CTX_DAG_ID='openweather_data_lake' AIRFLOW_CTX_TASK_ID='data_to_raw' AIRFLOW_CTX_EXECUTION_DATE='2025-01-25T12:22:19.895689+00:00' AIRFLOW_CTX_TRY_NUMBER='1' AIRFLOW_CTX_DAG_RUN_ID='manual__2025-01-25T12:22:19.895689+00:00'
[2025-01-25T12:22:21.679+0000] {taskinstance.py:1935} ERROR - Task failed with exception
Traceback (most recent call last):
  File "/home/airflow/.local/lib/python3.8/site-packages/airflow/operators/python.py", line 192, in execute
    return_value = self.execute_callable()
  File "/home/airflow/.local/lib/python3.8/site-packages/airflow/operators/python.py", line 209, in execute_callable
    return self.python_callable(*self.op_args, **self.op_kwargs)
  File "/opt/airflow/dags/openweather_data_lake.py", line 16, in run_data_recovery
    subprocess.run(["python", script_path], check=True)
  File "/usr/local/lib/python3.8/subprocess.py", line 516, in run
    raise CalledProcessError(retcode, process.args,
subprocess.CalledProcessError: Command '['python', '/opt/airflow/dags/./src/data-recovery.py']' returned non-zero exit status 2.
[2025-01-25T12:22:21.699+0000] {taskinstance.py:1398} INFO - Marking task as UP_FOR_RETRY. dag_id=openweather_data_lake, task_id=data_to_raw, execution_date=20250125T122219, start_date=20250125T122221, end_date=20250125T122221
[2025-01-25T12:22:21.718+0000] {standard_task_runner.py:104} ERROR - Failed to execute job 6 for task data_to_raw (Command '['python', '/opt/airflow/dags/./src/data-recovery.py']' returned non-zero exit status 2.; 390)
[2025-01-25T12:22:21.751+0000] {local_task_job_runner.py:228} INFO - Task exited with return code 1
[2025-01-25T12:22:21.788+0000] {taskinstance.py:2776} INFO - 0 downstream tasks scheduled from follow-on schedule check
