[2025-01-25T12:27:37.742+0000] {taskinstance.py:1157} INFO - Dependencies all met for dep_context=non-requeueable deps ti=<TaskInstance: openweather_data_lake.data_to_raw manual__2025-01-25T12:22:19.895689+00:00 [queued]>
[2025-01-25T12:27:37.756+0000] {taskinstance.py:1157} INFO - Dependencies all met for dep_context=requeueable deps ti=<TaskInstance: openweather_data_lake.data_to_raw manual__2025-01-25T12:22:19.895689+00:00 [queued]>
[2025-01-25T12:27:37.757+0000] {taskinstance.py:1359} INFO - Starting attempt 2 of 3
[2025-01-25T12:27:37.781+0000] {taskinstance.py:1380} INFO - Executing <Task(PythonOperator): data_to_raw> on 2025-01-25 12:22:19.895689+00:00
[2025-01-25T12:27:37.816+0000] {standard_task_runner.py:57} INFO - Started process 174 to run task
[2025-01-25T12:27:37.824+0000] {standard_task_runner.py:84} INFO - Running: ['***', 'tasks', 'run', 'openweather_data_lake', 'data_to_raw', 'manual__2025-01-25T12:22:19.895689+00:00', '--job-id', '9', '--raw', '--subdir', 'DAGS_FOLDER/openweather_data_lake.py', '--cfg-path', '/tmp/tmp72qlixaz']
[2025-01-25T12:27:37.828+0000] {standard_task_runner.py:85} INFO - Job 9: Subtask data_to_raw
[2025-01-25T12:27:37.880+0000] {logging_mixin.py:151} WARNING - /home/***/.local/lib/python3.8/site-packages/***/settings.py:195 DeprecationWarning: The sql_alchemy_conn option in [core] has been moved to the sql_alchemy_conn option in [database] - the old setting has been used, but please update your config.
[2025-01-25T12:27:37.960+0000] {task_command.py:415} INFO - Running <TaskInstance: openweather_data_lake.data_to_raw manual__2025-01-25T12:22:19.895689+00:00 [running]> on host 83d72546b46f
[2025-01-25T12:27:38.109+0000] {taskinstance.py:1660} INFO - Exporting env vars: AIRFLOW_CTX_DAG_OWNER='***' AIRFLOW_CTX_DAG_ID='openweather_data_lake' AIRFLOW_CTX_TASK_ID='data_to_raw' AIRFLOW_CTX_EXECUTION_DATE='2025-01-25T12:22:19.895689+00:00' AIRFLOW_CTX_TRY_NUMBER='2' AIRFLOW_CTX_DAG_RUN_ID='manual__2025-01-25T12:22:19.895689+00:00'
[2025-01-25T12:27:38.829+0000] {taskinstance.py:1935} ERROR - Task failed with exception
Traceback (most recent call last):
  File "/home/airflow/.local/lib/python3.8/site-packages/airflow/operators/python.py", line 192, in execute
    return_value = self.execute_callable()
  File "/home/airflow/.local/lib/python3.8/site-packages/airflow/operators/python.py", line 209, in execute_callable
    return self.python_callable(*self.op_args, **self.op_kwargs)
  File "/opt/airflow/dags/openweather_data_lake.py", line 16, in run_data_recovery
    subprocess.run(["python", script_path], check=True)
  File "/usr/local/lib/python3.8/subprocess.py", line 516, in run
    raise CalledProcessError(retcode, process.args,
subprocess.CalledProcessError: Command '['python', '/opt/airflow/dags/../src/data-recovery.py']' returned non-zero exit status 1.
[2025-01-25T12:27:38.856+0000] {taskinstance.py:1398} INFO - Marking task as UP_FOR_RETRY. dag_id=openweather_data_lake, task_id=data_to_raw, execution_date=20250125T122219, start_date=20250125T122737, end_date=20250125T122738
[2025-01-25T12:27:38.876+0000] {standard_task_runner.py:104} ERROR - Failed to execute job 9 for task data_to_raw (Command '['python', '/opt/airflow/dags/../src/data-recovery.py']' returned non-zero exit status 1.; 174)
[2025-01-25T12:27:38.916+0000] {local_task_job_runner.py:228} INFO - Task exited with return code 1
[2025-01-25T12:27:38.993+0000] {taskinstance.py:2776} INFO - 0 downstream tasks scheduled from follow-on schedule check
